<?xml version="1.0" encoding="UTF-8"?>
<!-- Generated by org.testng.reporters.JUnitReportReporter -->
<testsuite skipped="0" hostname="LAPTOP-OV4RUVE6" name="a1_keyWordTest.B2_TimeOutTest" tests="1" failures="0" timestamp="09 Jan 2023 08:46:17 GMT" time="4.034" errors="1">
  <testcase name="loginApp" time="4.034" classname="a1_keyWordTest.B2_TimeOutTest">
    <error type="org.testng.internal.thread.ThreadTimeoutException" message="Method a1_keyWordTest.B2_TimeOutTest.loginApp() didn&#039;t finish within the time-out 4000">
      <![CDATA[org.testng.internal.thread.ThreadTimeoutException: Method a1_keyWordTest.B2_TimeOutTest.loginApp() didn't finish within the time-out 4000at java.util.concurrent.FutureTask.setException(Unknown Source)at java.util.concurrent.FutureTask.run(Unknown Source)at java.util.concurrent.ThreadPoolExecutor.runWorker(Unknown Source)at java.util.concurrent.ThreadPoolExecutor$Worker.run(Unknown Source)at java.lang.Thread.run(Unknown Source)]]>
    </error>
  </testcase> <!-- loginApp -->
</testsuite> <!-- a1_keyWordTest.B2_TimeOutTest -->
